<?xml version="1.0" encoding="UTF-8"?>
<testng-results skipped="0" failed="2" ignored="0" total="2" passed="0">
  <reporter-output>
  </reporter-output>
  <suite name="Default suite" duration-ms="88231" started-at="2019-08-04T12:19:16Z" finished-at="2019-08-04T12:20:44Z">
    <groups>
    </groups>
    <test name="Default test" duration-ms="88231" started-at="2019-08-04T12:19:16Z" finished-at="2019-08-04T12:20:44Z">
      <class name="suites.LoginTestCase">
        <test-method status="PASS" signature="doInit()[pri:0, instance:suites.LoginTestCase@41eaa2]" name="doInit" is-config="true" duration-ms="49122" started-at="2019-08-04T12:19:19Z" finished-at="2019-08-04T12:20:08Z">
          <reporter-output>
          </reporter-output>
        </test-method> <!-- doInit -->
        <test-method status="FAIL" signature="loginTestCase(java.lang.String, java.lang.String, java.lang.String)[pri:0, instance:suites.LoginTestCase@41eaa2]" name="loginTestCase" duration-ms="10161" started-at="2019-08-04T12:20:08Z" data-provider="getData" finished-at="2019-08-04T12:20:18Z">
          <params>
            <param index="0">
              <value>
                <![CDATA[Tester]]>
              </value>
            </param>
            <param index="1">
              <value>
                <![CDATA[test1]]>
              </value>
            </param>
            <param index="2">
              <value>
                <![CDATA[Y]]>
              </value>
            </param>
          </params>
          <exception class="java.lang.AssertionError">
            <message>
              <![CDATA[expected [true] but found [false]]]>
            </message>
            <full-stacktrace>
              <![CDATA[java.lang.AssertionError: expected [true] but found [false]
at org.testng.Assert.fail(Assert.java:96)
at org.testng.Assert.failNotEquals(Assert.java:776)
at org.testng.Assert.assertTrue(Assert.java:44)
at org.testng.Assert.assertTrue(Assert.java:54)
at suites.LoginTestCase.loginTestCase(LoginTestCase.java:34)
at sun.reflect.NativeMethodAccessorImpl.invoke0(Native Method)
at sun.reflect.NativeMethodAccessorImpl.invoke(Unknown Source)
at sun.reflect.DelegatingMethodAccessorImpl.invoke(Unknown Source)
at java.lang.reflect.Method.invoke(Unknown Source)
at org.testng.internal.MethodInvocationHelper.invokeMethod(MethodInvocationHelper.java:124)
at org.testng.internal.Invoker.invokeMethod(Invoker.java:583)
at org.testng.internal.Invoker.invokeTestMethod(Invoker.java:719)
at org.testng.internal.Invoker.invokeTestMethods(Invoker.java:989)
at org.testng.internal.TestMethodWorker.invokeTestMethods(TestMethodWorker.java:125)
at org.testng.internal.TestMethodWorker.run(TestMethodWorker.java:109)
at org.testng.TestRunner.privateRun(TestRunner.java:648)
at org.testng.TestRunner.run(TestRunner.java:505)
at org.testng.SuiteRunner.runTest(SuiteRunner.java:455)
at org.testng.SuiteRunner.runSequentially(SuiteRunner.java:450)
at org.testng.SuiteRunner.privateRun(SuiteRunner.java:415)
at org.testng.SuiteRunner.run(SuiteRunner.java:364)
at org.testng.SuiteRunnerWorker.runSuite(SuiteRunnerWorker.java:52)
at org.testng.SuiteRunnerWorker.run(SuiteRunnerWorker.java:84)
at org.testng.TestNG.runSuitesSequentially(TestNG.java:1208)
at org.testng.TestNG.runSuitesLocally(TestNG.java:1137)
at org.testng.TestNG.runSuites(TestNG.java:1049)
at org.testng.TestNG.run(TestNG.java:1017)
at org.testng.remote.AbstractRemoteTestNG.run(AbstractRemoteTestNG.java:114)
at org.testng.remote.RemoteTestNG.initAndRun(RemoteTestNG.java:251)
at org.testng.remote.RemoteTestNG.main(RemoteTestNG.java:77)
]]>
            </full-stacktrace>
          </exception> <!-- java.lang.AssertionError -->
          <reporter-output>
          </reporter-output>
        </test-method> <!-- loginTestCase -->
        <test-method status="PASS" signature="tearDown()[pri:0, instance:suites.LoginTestCase@41eaa2]" name="tearDown" is-config="true" duration-ms="983" started-at="2019-08-04T12:20:18Z" finished-at="2019-08-04T12:20:19Z">
          <reporter-output>
          </reporter-output>
        </test-method> <!-- tearDown -->
        <test-method status="PASS" signature="doInit()[pri:0, instance:suites.LoginTestCase@41eaa2]" name="doInit" is-config="true" duration-ms="14794" started-at="2019-08-04T12:20:19Z" finished-at="2019-08-04T12:20:34Z">
          <reporter-output>
          </reporter-output>
        </test-method> <!-- doInit -->
        <test-method status="FAIL" signature="loginTestCase(java.lang.String, java.lang.String, java.lang.String)[pri:0, instance:suites.LoginTestCase@41eaa2]" name="loginTestCase" duration-ms="9058" started-at="2019-08-04T12:20:34Z" data-provider="getData" finished-at="2019-08-04T12:20:43Z">
          <params>
            <param index="0">
              <value>
                <![CDATA[Tester]]>
              </value>
            </param>
            <param index="1">
              <value>
                <![CDATA[test]]>
              </value>
            </param>
            <param index="2">
              <value>
                <![CDATA[N]]>
              </value>
            </param>
          </params>
          <exception class="java.lang.AssertionError">
            <message>
              <![CDATA[expected [true] but found [false]]]>
            </message>
            <full-stacktrace>
              <![CDATA[java.lang.AssertionError: expected [true] but found [false]
at org.testng.Assert.fail(Assert.java:96)
at org.testng.Assert.failNotEquals(Assert.java:776)
at org.testng.Assert.assertTrue(Assert.java:44)
at org.testng.Assert.assertTrue(Assert.java:54)
at suites.LoginTestCase.loginTestCase(LoginTestCase.java:38)
at sun.reflect.NativeMethodAccessorImpl.invoke0(Native Method)
at sun.reflect.NativeMethodAccessorImpl.invoke(Unknown Source)
at sun.reflect.DelegatingMethodAccessorImpl.invoke(Unknown Source)
at java.lang.reflect.Method.invoke(Unknown Source)
at org.testng.internal.MethodInvocationHelper.invokeMethod(MethodInvocationHelper.java:124)
at org.testng.internal.Invoker.invokeMethod(Invoker.java:583)
at org.testng.internal.Invoker.invokeTestMethod(Invoker.java:719)
at org.testng.internal.Invoker.invokeTestMethods(Invoker.java:989)
at org.testng.internal.TestMethodWorker.invokeTestMethods(TestMethodWorker.java:125)
at org.testng.internal.TestMethodWorker.run(TestMethodWorker.java:109)
at org.testng.TestRunner.privateRun(TestRunner.java:648)
at org.testng.TestRunner.run(TestRunner.java:505)
at org.testng.SuiteRunner.runTest(SuiteRunner.java:455)
at org.testng.SuiteRunner.runSequentially(SuiteRunner.java:450)
at org.testng.SuiteRunner.privateRun(SuiteRunner.java:415)
at org.testng.SuiteRunner.run(SuiteRunner.java:364)
at org.testng.SuiteRunnerWorker.runSuite(SuiteRunnerWorker.java:52)
at org.testng.SuiteRunnerWorker.run(SuiteRunnerWorker.java:84)
at org.testng.TestNG.runSuitesSequentially(TestNG.java:1208)
at org.testng.TestNG.runSuitesLocally(TestNG.java:1137)
at org.testng.TestNG.runSuites(TestNG.java:1049)
at org.testng.TestNG.run(TestNG.java:1017)
at org.testng.remote.AbstractRemoteTestNG.run(AbstractRemoteTestNG.java:114)
at org.testng.remote.RemoteTestNG.initAndRun(RemoteTestNG.java:251)
at org.testng.remote.RemoteTestNG.main(RemoteTestNG.java:77)
]]>
            </full-stacktrace>
          </exception> <!-- java.lang.AssertionError -->
          <reporter-output>
          </reporter-output>
        </test-method> <!-- loginTestCase -->
        <test-method status="PASS" signature="tearDown()[pri:0, instance:suites.LoginTestCase@41eaa2]" name="tearDown" is-config="true" duration-ms="1221" started-at="2019-08-04T12:20:43Z" finished-at="2019-08-04T12:20:44Z">
          <reporter-output>
          </reporter-output>
        </test-method> <!-- tearDown -->
      </class> <!-- suites.LoginTestCase -->
    </test> <!-- Default test -->
  </suite> <!-- Default suite -->
</testng-results>
